Workbook

Sheet Main
G5: Market Risk Management
B10: Valuation model for MM instruments
B11: version 0.1
B14: Applicable for products: | E14: [code] | F14: [Clean Lending/Placement interbank]
E15: [code] | F15: [Clean Deposit/Borrowing interbank]
E16: [code] | F16: [Collateralized Lending/Placement interbank]
E17: [code] | F17: [ Collateralized Deposit/Borrowing interbank]
E18: [code] | F18: [ Repo]
E19: [code] | F19: [ Reverse repo]
B22: Model developed by: | G22: [dungnt52]
B23: Approved by | G23: [RCO]
B24: Approval date | G24: [approval date]
B25: Next review date | G25: [review date]
B28: Content
B29: 1. Description | E29: 4. Fair Value Level
B30: 2. Model inputs | E30: 5. Calculation formulas
B31: 3. Unobservable inputs | E31: 6. Example

Sheet 1. Description
B3: =Main!B10 -> Valuation model for MM instruments
B5: Desciption
B7: The valuation model is a classical discounted cash flows model and provides fair value of money market instruments with fixed rate including loans and placements at other FIs, deposit and borrowing, repo, reverse repo from other FIs. The computation process is as follows: Step 1: Estimation of all cash flows (both principal and interest, if any) that occur after the evaluation date and till the final maturity; Step 2: mapping of cash flows to discount factors derived from interest rate curves in Vietnam interbank offered rate (VNIBOR), international interbank offered rate (refer to valuation inputs), day count convention, holiday convention and computation of discounted cash flows as a product of future cash flows and discount rate. The sum of discounted cash flows is present value of these cash flows.
B9: Model uncertainties and risk
B11: Since the discounted cash flows approach is globally used method of MM instruments pricing, model uncertainties are negligible. The valuation uncertainties are: - Limited to those driven by interpolation of valuation curve and are generally assessed as low. - Limited to valuation inputs

Sheet 2. Model inputs
B3: =Main!B10 -> Valuation model for MM instruments
B6: Observable inputs * | H6: (see explanation below)
B8: Input name | D8: Reference to market data | F8: Application
B9: Vnibor VND zero rate | D9: VNIBOR | F9: Lending/Borrowing VND from local FIs
B10: Vnibor USD zero rate in Vietnamese market | D10: VNIBOR | F10: Lending/Borrowing USD from local FIs
B11: Discount USD zero rate in International market | D11: Reuters | F11: Lending/Borrowing USD from international FIs
B12: Discount EUR zero rate in International market | D12: Reuters | F12: Lending/Borrowing EUR from international FIs
B13: Discount GBP zero rate in International market | D13: Reuters | F13: Lending/Borrowing GBP from international FIs
B14: Discount AUD zero rate in International market | D14: Reuters | F14: Lending/Borrowing AUD from international FIs
B15: Discount CAD zero rate in International market | D15: Reuters | F15: Lending/Borrowing CAD from international FIs
B16: Discount JPY zero rate in International market | D16: Reuters | F16: Lending/Borrowing JPY from international FIs
B17: Discount CNY zero rate in International market | D17: Reuters | F17: Lending/Borrowing CNY from international FIs
B18: Discount CHF zero rate in International market | D18: Reuters | F18: Lending/Borrowing CHF from international FIs
B19: Discount SGD zero rate in International market | D19: Reuters | F19: Lending/Borrowing SGD from international FIs
... B21: Discount THB zero curve in international market | D21: Reuters | F21: Lending/Borrowing THB from international FIs
B22: For lending/borrowing of other foreign currencies (except USD) from other local FIs, the curves are constructed from: + Apply the same curves as lending/borrowing of USD from other local FIs (Vnibor USD zero rate in Vietnamese market) as prompted by local practice due to the illquidity of that currency in Vietnamese market; + Add 20 basis point illiquid spread.
B23: MM instrument is a bullet amortization product and the original term is less then or equal to 1 year, therefore the above curves are zero curve
B25: Unobservable inputs ** | H25: (see explanation below)
B27: Input name | D27: Description
B36: Observable and unobservable inputs

Sheet 3. Unobservable inputs
B3: =Main!B10 -> Valuation model for MM instruments
B5: Unobservable inputs derivation
B7: This model does not have any unobservable imputs.
B10: Unobservable inputs monitoring

Sheet 4. Fair Value Level
B3: =Main!B10 -> Valuation model for MM instruments
B5: Fair value level concideration
B7: The application of the model will result in: Fair Value Level 2.
B11: Rationals:
B13: The valuation model has solely observable valuation inputs, well known to other market participants and directly observed on the market.

Sheet 5. Calculation formulas
B2: =Main!B10 -> Valuation model for MM instruments
B4: Formulas for fair value calculation
B10: here
B11: CF stands for cash flows
B12: Discount factor is taken into account day count convention and holiday convention,d: equal to number of accrued days,T: total days in a coupon payment period
B13: Discount factor is identified based on the discount rate (symbol "r" in the formula) matrix below
B15: Currency | C15: Local | D15: International
B16: VND | C16: Vnibor VND zero rate | D16: N/A
C17: Ngày 14/09/2017
B18: aud | C18: 18273 | D18: 18195
B19: usd | C19: 22726 | D19: 22726
B20: tỷ giá ON USD | C20: 0.0131 | D20: 0.0131
C21: =C18/C19 -> 0.80405703 | D21: =D18/D19 -> 0.80062483
B22: tỷ giá tính toán | C22: =C21*C20 -> 0.010533147 | D22: =D21*D20 -> 0.010488185
B23: tỷ giá cho vay thật | C23: 0.01 | D23: 0.01
C26: Ngày 19/01/2017
B27: eur | C27: 24135 | D27: 24145
B28: usd | C28: 22622 | D28: 22574
B29: tỷ giá ON USD | C29: 0.012 | D29: 0.012
C30: =C27/C28 -> 1.0668818 | D30: =D27/D28 -> 1.0695933
B31: tỷ giá tính toán | C31: =C30*C29 -> 0.012802582 | D31: =D30*D29 -> 0.01283512
B32: tỷ giá cho vay thật | C32: 0.012 | D32: 0.012
C35: Ngày 05/07/2017
B36: cad | C36: 17495 | D36: 17570
B37: usd | C37: 22737 | D37: 22744
B38: tỷ giá ON USD | C38: 0.0132 | D38: 0.0131
C39: =C36/C37 -> 0.76945068 | D39: =D36/D37 -> 0.77251143
B40: tỷ giá tính toán | C40: =C39*C38 -> 0.010156749 | D40: =D39*D38 -> 0.0101199
B41: tỷ giá cho vay thật | C41: 0.02 | D41: 0.02
C44: Ngày 05/01/2017
B45: JPY | C45: 192.85 | D45: 194.7
B46: usd | C46: 22735 | D46: 22683
B47: tỷ giá ON USD | C47: 0.0115 | D47: 0.0111
C48: =C45/C46 -> 0.0084825159 | D48: =D45/D46 -> 0.0085835207
B49: tỷ giá tính toán | C49: =C48*C47 -> 9.7548933e-05 | D49: =D48*D47 -> 9.527708e-05
B50: tỷ giá cho vay thật | C50: 0.01 | D50: 0.01
C53: Ngày 05/01/2017 | H53: Ngày 12/07/2017
B54: SGD | C54: 15690 | D54: 15755 | H54: 16425 | I54: 16455
B55: usd | C55: 22735 | D55: 22683 | H55: 22735 | I55: 22735
B56: tỷ giá ON USD | C56: 0.0115 | D56: 0.0111 | H56: 0.0134 | I56: 0.0133
...

Sheet 6. Example
B2: =Main!B10 -> Valuation model for MM instruments
B4: Example
B6: VPBank give a 1-month loan to BVB in VND and require no collateral
B9: Assumed input parameters
B11: Transaction static data | F11: Tenor | G11: VNIBOR_VND | H11: Number of days
B12: Principal amount | C12: 300000000000 | F12: ON | G12: 0.0153 | H12: 1
B13: Value date | C13: 43824 | F13: 1W | G13: 0.0237 | H13: 7
B14: Maturity date | C14: 43838 | F14: 2W | G14: 0.0313 | H14: 14
B15: Reporting date | C15: 43829
B16: Original term | C16: =C14-C13 -> 14
B17: Remaining term | C17: =C14-C15 -> 9
B18: Contracted Interest rate | C18: 0.033
B19: Interest rate type | C19: fixed
B20: Amortization type | C20: bullet
B21: Day count convention | C21: ACT/365
B24: Calculation
B26: Step 1. Calculation of new present value of future cash flows
B28: Cash flow dates | C28: Cash flow amount
B29: 43838 | C29: 300000000000
B30: 43838 | C30: =C12*((C14-C13)/365)*C18 -> 3.7972603e+08
B33: Step 2a. Interpolation calculation of interest rate
B35: Reporting date | D35: 43829
B36: interest rate of remaining term | D36: =((H14-C17)*G13+(C17-H13)*G14)/(H14-H13) -> 0.025871429
B38: Step 2b. Finilization
B40: Reporting date | C40: Cash flow amount | D40: Discounted cash flows
B41: 43838 | C41: =C29 -> 300000000000 | D41: =C41/(1+D36*C17/365) -> 2.9980874e+11
B42: 43838 | C42: =C30 -> 3.7972603e+08 | D42: =C42/(1+D36*C17/365) -> 3.7948394e+08
B43: Fair value of deal | D43: =SUM(D41:D42) -> 3.0018823e+11
