Workbook

Sheet MAIN
G5: Market Risk Management
B10: Valuation model for IRS
B11: version 0.1
B14: Applicable for products: | E14: IRS | F14: Interest rate swaps
B20: Model developed by: | F20: Linh Le Thi (RMD - CMD) <linhlt5@vpbank.com.vn>
B21: Approved by: | G21: RCO
B22: Approval date: | G22: tbd
B23: Next review date: | G23: tbd
B27: Content
B28: 1. Description | E28: 5. Calculation formulas
B29: 2. Model inputs | E29: 6. Example
B30: 3. Unobservable inputs
B31: 4. Fair value level

Sheet 1. Description
B3: =MAIN!B10 -> Valuation model for IRS
B5: Desciption
B7: The valuation model is a classical discounted cash flows model. The computation process consist from 3 steps: Step1: estimation of all cash flows that occur after the evaluation date and till the final maturity (using zero rate to generate forward rate, if necessary). Step 2: mapping of cash flows to discount factors derived from zero curves (refer to model inputs), day count convention, holiday convention and computation of discounted cash flows as a product of future cash flows and discount rate. The sum of discounted cash flows is present value of these cash flows. Step 3: Convert fair value into local currency.
B8: Note: - To construct accurately cash flows, it's necessary to know about day count convention and holiday convention. - Since bid-ask spread in VND curve is quite big, receive leg will be valuated by applying bid rate and the other will apply ask rate. For other currencies, mid rate will be applied for both legs due to small spread.
B9: Model uncertainties and risk
B11: Since the discounted cash flows approach is globally used method of IRS pricing, model uncertainties are negligible. The valuation uncertainties are limited to those driven by interpolation of valuation curve and are generally assessed as low. Model risk is due to the lack of availability of VND swap curve in Vietnam market. Therefore, VND zero curve is derived from Deposit VND par curve by using bootstrapping.

Sheet 2. Model inputs
B3: =MAIN!B10 -> Valuation model for IRS
B6: Observable inputs * | H6: (see explanation below)
B8: Input name | D8: Reference to market data
B9: USD zero curve | D9: USD semi bond 1M Libor zero coupon yield curve
D10: USD semi bond 3M Libor zero coupon yield curve
D11: USD semi bond 6M Libor zero coupon yield curve
D12: USD semi bond 1Y Libor zero coupon yield curve
B13: EUR zero curve | D13: EUR annual money 1M Euribor zero coupon yield curve
D14: EUR annual money 3M Euribor zero coupon yield curve
D15: EUR annual money 6M Euribor zero coupon yield curve
D16: EUR annual money 1Y Euribor zero coupon yield curve
B17: USD discount curve | D17: USD zero coupon yield curve
B18: EUR discount curve | D18: EUR zero coupon yield curve
B19: VND discount curve & zero curve | D19: Deposit VND par rate + Risk premium
B20: CHF discount curve & zero curve | D20: CHF zero coupon yield curve
B21: CAD discount curve & zero curve | D21: CAD zero coupon yield curve
B22: CNY discount curve & zero curve | D22: CNY zero coupon yield curve
B23: SGD discount curve & zero curve | D23: SGD zero coupon yield curve
B24: AUD discount curve & zero curve | D24: AUD zero coupon yield curve
B25: JPY discount curve & zero curve | D25: JPY zero coupon yield curve
B26: GBP discount curve & zero curve | D26: GBP zero coupon yield curve
B27: THB discount curve & zero curve | D27: THB zero coupon yield curve
B28: HKD discount curve & zero curve | D28: HKD zero coupon yield curve
B30: Note:
B32: All the information are collected from Reuter
B34: Unobservable inputs ** | H34: (see explanation below)
B36: Input name | D36: Description
B48: Observable and unobservable inputs
B50: Observable inputs *: Observable inputs are valuation inputs seen at an outside source available to market participants. Examples of observable valuation inputs are: - market quotes; - quoted curves; - calculated curves derived from quoted curves; - derived curves (for example derived zero curves) under the condition that only widely accepted calculation methods are used. Unobservable inputs **: Unobservable inputs are valuation inputs that are not available on the market, but produced by the institution. Examples of unobservable valuation inputs are: - internal ratings and related probabilities of default; - derived curves with the usage of non standard methods; - valuation statements provided by 3rd parties.

Sheet 3. Unobservable inputs
B3: =MAIN!B10 -> Valuation model for IRS
B5: Unobservable inputs derivation
B7: This model does not have any unobservable imputs.
B10: Unobservable inputs monitoring
B12: [what are the conditions for re-concideration of unobservable inputs]

Sheet 4. Fair Value Level
B3: =MAIN!B10 -> Valuation model for IRS
B5: Fair value level concideration
B7: The application of the model will result in: Fair Value Level 2
B11: Rationals:
B12: The valuation model mostly consist of observable valuation inputs direct or indirectly, well known to other market participants and directly observed on the market.

Sheet 5. Calculation formulas
B3: =MAIN!B10 -> Valuation model for IRS
B5: Formulas for fair value calculation
B7: Forward rate is an interest rate calculated based on certain curves for rest payment periods of floating interest rate contracts.
B8: where: DF(0,t1): discounted factor at t1 DF(0,t2): discounted factor at t2 t2, t1: tenor of reference interest rate r: forward rate
B11: Present value of cash flow:
B16: where:
B17: CF stands for cash flows
B18: Discount factor: available information from Reuter

Sheet 6. Example
B3: =MAIN!B10 -> Valuation model for IRS
B5: Example
B7: [Example description]
B10: Assumed input parameters | F10: Discount curve | J10: 6M Zero curve
B11: Contract information: | F11: Tenor | G11: Rate | H11: Number of days | J11: Tenor | K11: Rate | L11: Number of days
B12: Currency | C12: USD | F12: 1M | G12: 0.01251396 | H12: 30 | J12: 1M | K12: 0.01252744 | L12: 30
B13: Tenor | C13: 2Y | F13: 2M | G13: 0.01270742 | H13: 60 | J13: 2M | K13: 0.01343059 | L13: 60
B14: Principal amount | C14: 50000000 | F14: 3M | G14: 0.01291101 | H14: 90 | J14: 3M | K14: 0.01413612 | L14: 90
B15: Fixed rate | C15: 0.0202 | F15: 6M | G15: 0.01354573 | H15: 180 | J15: 6M | K15: 0.01469279 | L15: 180
B16: Floating rate | C16: Libor 6M | F16: 9M | G16: 0.01409445 | H16: 270 | J16: 9M | K16: 0.01516589 | L16: 270
B17: VPBank | C17: pay fixed & receive float | F17: 1Y | G17: 0.01455822 | H17: 365 | J17: 1Y | K17: 0.01559898 | L17: 365
B18: Interest payment | C18: Semi-annual | F18: 2Y | G18: 0.01599135 | H18: 730 | J18: 2Y | K18: 0.01707371 | L18: 730
B19: Day count convention | C19: Act/360 | F19: 3Y | G19: 0.01719889 | H19: 1095 | J19: 3Y | K19: 0.01833383 | L19: 1095
B20: Floating rate for initial period | C20: 0.0136646
B21: Notional amount's feature | C21: reduced 10 mln in each period
B22: Evaluation date | C22: 42947
B23: Spot rate at 31-Jul-17 | C23: 22740
B25: Calculation
B27: Step 1a. Identify cash flow for floating leg
B29: Time remaining (months) | C29: Spot rate | D29: DF | E29: 6M Fwd rate | F29: Discount rate
B30: =(C38-$C$22) -> 46 | C30: =K12+(B30-L12)/(L13-L12)*(K13-K12) -> 0.01300912 | D30: =1/(1+C30)^(B30/360) -> 0.99834981 | E30: =C20 -> 0.0136646 | F30: =G12+(B30-H12)/(H13-H12)*(G13-G12) -> 0.012617139
B31: =(C39-$C$22) -> 227 | C31: =K15+(B31-L15)/(L16-L15)*(K16-K15) -> 0.014939853 | D31: =1/(1+C31)^(B31/360) -> 0.99069285 | E31: =(D30/D31-1)*360/(B31-B30) -> 0.015372376 | F31: =G15+(B31-H15)/(H16-H15)*(G16-G15) -> 0.013832284
B32: =(C40-$C$22) -> 413 | C32: =K17+(B32-L17)/(L18-L17)*(K18-K17) -> 0.015792917 | D32: =1/(1+C32)^(B32/360) -> 0.98218421 | E32: =(D31/D32-1)*360/(B32-B31) -> 0.016767065 | F32: =G17+(B32-H17)/(H18-H17)*(G18-G17) -> 0.014746686
B33: =(C41-$C$22) -> 592 | C33: =K17+(B33-L17)/(L18-L17)*(K18-K17) -> 0.016516141 | D33: =1/(1+C33)^(B33/360) -> 0.97342157 | E33: =(D32/D33-1)*360/(B33-B32) -> 0.018104373 | F33: =G17+(B33-H17)/(H18-H17)*(G18-G17) -> 0.015449509
B34: =(C42-$C$22) -> 777 | C34: =K18+(B34-L18)/(L19-L18)*(K19-K18) -> 0.017235972 | D34: =1/(1+C34)^(B34/360) -> 0.96378792 | E34: =(D33/D34-1)*360/(B34-B33) -> 0.019450918 | F34: =G18+(B34-H18)/(H19-H18)*(G19-G18) -> 0.016146841
B36: Step 1b: Calculation of all future cash flows:
B37: Start date | C37: End date | D37: Notional amount | E37: Fixed CF | F37: Floating CF
B38: 42828 | C38: 42993 | D38: 50000000 | E38: =D38*$C$15*(C38-B38)/360 -> 462916.67 | F38: =D38*E30*(C38-B38)/360 -> 313147.08
B39: 42993 | C39: 43174 | D39: 40000000 | E39: =D39*$C$15*(C39-B39)/360 -> 406244.44 | F39: =D39*E31*(C39-B39)/360 -> 309155.55
B40: 43174 | C40: 43360 | D40: 30000000 | E40: =D40*$C$15*(C40-B40)/360 -> 313100 | F40: =D40*E32*(C40-B40)/360 -> 259889.51
B41: 43360 | C41: 43539 | D41: 20000000 | E41: =D41*$C$15*(C41-B41)/360 -> 200877.78 | F41: =D41*E33*(C41-B41)/360 -> 180037.93
B42: 43539 | C42: 43724 | D42: 10000000 | E42: =D42*$C$15*(C42-B42)/360 -> 103805.56 | F42: =D42*E34*(C42-B42)/360 -> 99956.108
B45: Step 2a. Calculation of present value of future cash flows
B47: Start date | C47: End date | D47: Time remaining (days) | E47: Discount factor of discount rate | F47: PV of fixed leg | G47: PV of floating leg
B48: 42828 | C48: 42993 | D48: =C48-$C$22 -> 46 | E48: =1/(1+F30)^(D48/360) -> 0.99839918 | F48: =E38*E48 -> 462175.62 | G48: =F38*E48 -> 312645.79
B49: 42993 | C49: 43174 | D49: =C49-$C$22 -> 227 | E49: =1/(1+F31)^(D49/360) -> 0.99137516 | F49: =E39*E49 -> 402740.65 | G49: =F39*E49 -> 306489.13
B50: 43174 | C50: 43360 | D50: =C50-$C$22 -> 413 | E50: =1/(1+F32)^(D50/360) -> 0.98334604 | F50: =E40*E50 -> 307885.64 | G50: =F40*E50 -> 255561.32
B51: 43360 | C51: 43539 | D51: =C51-$C$22 -> 592 | E51: =1/(1+F33)^(D51/360) -> 0.97510355 | F51: =E41*E51 -> 195876.64 | G51: =F41*E51 -> 175555.63
B52: 43539 | C52: 43724 | D52: =C52-$C$22 -> 777 | E52: =1/(1+F34)^(D52/360) -> 0.96601888 | F52: =E42*E52 -> 100278.13 | G52: =F42*E52 -> 96559.488
B54: Step 2b. Fair value
...
